Workbook

Sheet Uputstvo
A1: AgriX — Finansijski model
A2: Verzija 1 · 26.07.2026. · sve cene u EUR, na godišnjem nivou, bez PDV-a
A4: BOJE
A5: Plavo — ulazna vrednost koju menjaš. Sve plavo je pretpostavka ili odluka.
A6: Crno — formula. Ne menjaj.
A7: Zeleno — veza ka drugom listu.
A8: Žuta pozadina — mora se popuniti pre nego što model ima smisla.
A10: LISTOVI
A11: Pretpostavke — jedino mesto gde se menjaju ulazi. Cene su preuzete iz Decision Loga.
A12: Prihod — godišnji prihod po profilu klijenta i po scenariju.
A13: Kapacitet — koliko sati traži baza klijenata i kada osnivač postaje usko grlo.
A14: CashFlow — mesečni tok, sa uplatama koncentrisanim pre sezone.
... A24: Okidač za zapošljavanje: BC3 i 336 — najkasnije pri 15–20 firmi ili pre sezone 2027.

Sheet Pretpostavke
A1: Pretpostavke
A2: Plava polja su ulazi. Žuta se moraju popuniti.
A4: A. Cenovnik
A5: Stavka | B5: Cena | G5: Izvor
A6: Desktop Core | B6: 500 | G6: odluka 349
A7: Desktop all-in | B7: 1200 | G7: odluka 349 (revizija 27.07.) — bazna 500 + 700
A8: Mobile | B8: 1500 | G8: odluka 349
A9: Mobile all-in | B9: 2200 | G9: odluka 349 (revizija 27.07.) — bazna 1.500 + 700
A10: Stanica preko pet | B10: 50 | G10: odluka 351
A11: Modul (SEF / Banka / Dispatch) | B11: 200 | G11: odluka 350
A12: Modul Hladnjača / Proizvodnja | B12: 400 | G12: odluka 350
A13: GGAP | B13: 1000 | G13: odluka 352
A14: Gazdinstvo Pro — kanalska cena | B14: 20 | G14: odluka 339
A15: Gazdinstvo Basic — kanalska cena | B15: 10 | G15: odluka 339
A16: Savetnik — osnovica | B16: 150 | G16: odluka 419 — standalone tarifa
A17: Savetnik — po gazdinstvu preko 10 | B17: 15 | G17: odluka 419 — standalone, preko 10
... A20: Satnica — obuka | B20: 30 | G20: odluka 354
A22: B. Profil prosečnog klijenta
A23: Parametar | B23: Vrednost | G23: Napomena
A24: Prosečan broj otkupnih stanica | B24: 10 | G24: iz postojeće baze
A25: Uključeno stanica u osnovnoj ceni | B25: 5 | G25: odluka 298
A26: Prosečan broj kooperanata | B26: 100 | G26: iz postojeće baze
A27: Konverzija kooperanata na Pro | B27: 0.05 | G27: pretpostavka
A28: Udeo klijenata koji uzima GGAP | B28: 0.2 | G28: pretpostavka
A29: Udeo klijenata sa hardverskom podrškom | B29: 0.5 | G29: pretpostavka
A31: C. Struktura baze klijenata
A32: Profil | B32: Udeo | G32: Napomena
A33: Desktop Core | B33: 0.3
A34: Desktop all-in | B34: 0.35
A35: Mobile all-in | B35: 0.35
A36: Ukupno | B36: =SUM(B33:B35) | G36: mora biti 100%
A38: D. Scenariji rasta do sezone 2027
A39: Scenario | B39: Novih klijenata | C39: Postojećih | D39: Ukupno | G39: Napomena
A40: A — konzervativni | B40: 5 | C40: 3 | D40: =B40+C40
A41: B — balansirani | B41: 8 | C41: 3 | D41: =B41+C41
A42: C — agresivni | B42: 14 | C42: 3 | D42: =B42+C42 | G42: izabran, odluka 375
A44: E. Kapacitet osnivača
A45: Parametar | B45: Vrednost | G45: Napomena
A46: Radnih sati nedeljno | B46: 60 | G46: unesi realnu vrednost
A47: Radnih nedelja godišnje | B47: 50
...

Sheet Prihod
A1: Prihod
A2: Godišnji prihod po profilu klijenta, izveden iz Pretpostavki.
A4: A. Prihod po jednom klijentu
A5: Komponenta | B5: Desktop Core | C5: Desktop all-in | D5: Mobile all-in | F5: Formula / napomena
A6: Osnovni paket | B6: =Pretpostavke!$B$6 | C6: =Pretpostavke!$B$7 | D6: =Pretpostavke!$B$9 | F6: cene iz odluke 349
A7: Dodatne stanice | B7: =(Pretpostavke!$B$24-Pretpostavke!$B$25)*Pretpostavke!$B$10 | C7: =(Pretpostavke!$B$24-Pretpostavke!$B$25)*Pretpostavke!$B$10 | D7: =(Pretpostavke!$B$24-Pretpostavke!$B$25)*Pretpostavke!$B$10 | F7: prosečan broj minus uključene, po ceni iz 351
A8: GGAP | B8: =Pretpostavke!$B$13*Pretpostavke!$B$28 | C8: =Pretpostavke!$B$13*Pretpostavke!$B$28 | D8: =Pretpostavke!$B$13*Pretpostavke!$B$28 | F8: očekivana vrednost prema udelu
A9: Gazdinstvo Pro | B9: =Pretpostavke!$B$26*Pretpostavke!$B$27*Pretpostavke!$B$14 | C9: =Pretpostavke!$B$26*Pretpostavke!$B$27*Pretpostavke!$B$14 | D9: =Pretpostavke!$B$26*Pretpostavke!$B$27*Pretpostavke!$B$14 | F9: kooperanti × konverzija × kanalska cena
A10: Hardverska podrška | B10: =Pretpostavke!$B$24*Pretpostavke!$B$18*Pretpostavke!$B$29 | C10: =Pretpostavke!$B$24*Pretpostavke!$B$18*Pretpostavke!$B$29 | D10: =Pretpostavke!$B$24*Pretpostavke!$B$18*Pretpostavke!$B$29 | F10: stanice × cena × udeo klijenata
A11: Savetnik — Enterprise tarifa | B11: =(Pretpostavke!$B$69)*Pretpostavke!$B$72 | C11: =(Pretpostavke!$B$69)*Pretpostavke!$B$72 | D11: =(Pretpostavke!$B$69)*Pretpostavke!$B$72 | F11: osnovica x broj licenci; 0 dok se ne popuni pretpostavka
A12: Hladnjaca/Proizvodnja — dodatni pogoni | B12: =Pretpostavke!$B$71*Pretpostavke!$B$73 | C12: =Pretpostavke!$B$71*Pretpostavke!$B$73 | D12: =Pretpostavke!$B$71*Pretpostavke!$B$73 | F12: cena po dodatnom pogonu x broj pogona; 0 dok se ne popuni
A13: Ukupno po klijentu | B13: =SUM(B6:B12) | C13: =SUM(C6:C12) | D13: =SUM(D6:D12)
A15: B. Prihod po scenariju
A16: Scenario | B16: Ukupno klijenata | C16: Prosečan prihod | D16: Ukupan ARR | F16: Napomena
A17: Scenario A | B17: =Pretpostavke!$D$40 | C17: =$B$13*Pretpostavke!$B$33+$C$13*Pretpostavke!$B$34+$D$13*Pretpostavke!$B$35 | D17: =B17*C17
A18: Scenario B | B18: =Pretpostavke!$D$41 | C18: =$B$13*Pretpostavke!$B$33+$C$13*Pretpostavke!$B$34+$D$13*Pretpostavke!$B$35 | D18: =B18*C18
A19: Scenario C | B19: =Pretpostavke!$D$42 | C19: =$B$13*Pretpostavke!$B$33+$C$13*Pretpostavke!$B$34+$D$13*Pretpostavke!$B$35 | D19: =B19*C19 | F19: izabran
A22: Prosečan prihod je ponderisan strukturom baze iz odeljka C Pretpostavki. Model ne razlikuje postojeće klijente po staroj ceni (odluka 334) — za prvu godinu njihov prihod treba uneti posebno.

Sheet Kapacitet
A1: Kapacitet
A2: Koliko sati traži baza klijenata i kada osnivač postaje usko grlo.
A4: A. Raspoloživo vreme
A5: Ukupno sati godišnje | B5: =Pretpostavke!$B$46*Pretpostavke!$B$47
A7: B. Potrebno vreme po broju klijenata
A8: Stavka | B8: 8 klijenata | C8: 12 klijenata | D8: 18 klijenata | F8: Napomena
A9: Podrška van sezone | B9: =8*Pretpostavke!$B$49*(Pretpostavke!$B$47-Pretpostavke!$B$51) | C9: =12*Pretpostavke!$B$49*(Pretpostavke!$B$47-Pretpostavke!$B$51) | D9: =18*Pretpostavke!$B$49*(Pretpostavke!$B$47-Pretpostavke!$B$51) | F9: klijenti × sati nedeljno × nedelja
A10: Podrška u sezoni | B10: =8*Pretpostavke!$B$50*Pretpostavke!$B$51 | C10: =12*Pretpostavke!$B$50*Pretpostavke!$B$51 | D10: =18*Pretpostavke!$B$50*Pretpostavke!$B$51 | F10: jun–novembar
A11: Onboarding novih | B11: =(8-3)*Pretpostavke!$B$48 | C11: =(12-3)*Pretpostavke!$B$48 | D11: =(18-3)*Pretpostavke!$B$48 | F11: samo novi klijenti
A12: Prodaja | B12: =(8-3)*Pretpostavke!$B$52 | C12: =(12-3)*Pretpostavke!$B$52 | D12: =(18-3)*Pretpostavke!$B$52 | F12: uključuje neuspele prospekte
A13: Ukupno potrebno | B13: =SUM(B9:B12) | C13: =SUM(C9:C12) | D13: =SUM(D9:D12)
A14: Preostalo za razvoj | B14: =$B$5-B13 | C14: =$B$5-C13 | D14: =$B$5-D13
A15: Cilj za razvoj | B15: =Pretpostavke!$B$53 | C15: =Pretpostavke!$B$53 | D15: =Pretpostavke!$B$53
A16: Status | B16: =IF(B14>=B15,"u granicama","NEDOSTAJE VREMENA") | C16: =IF(C14>=C15,"u granicama","NEDOSTAJE VREMENA") | D16: =IF(D14>=D15,"u granicama","NEDOSTAJE VREMENA")
A18: C. Okidač za zapošljavanje
A19: Odluka BC3 i 336: druga tehnički ovlašćena osoba uvodi se najkasnije pri 15–20 aktivnih firmi.
A20: Sezona jun–novembar (odluka 378) znači šest meseci pojačane podrške, pa okidač u praksi pada pre 1. juna 2027.
A21: Ako red Status pokazuje da nedostaje vremena već pri 12 klijenata, zapošljavanje ne čeka brojku iz BC3.

Sheet CashFlow
A1: Mesečni tok novca — scenario C
A2: Uplate su koncentrisane pre sezone (odluke 325, 326).
A4: Stavka | B4: Jan | C4: Feb | D4: Mar | E4: Apr | F4: Maj | G4: Jun | H4: Jul | I4: Avg | J4: Sep | K4: Okt | L4: Nov | M4: Dec | N4: Ukupno
A5: Raspored uplata (%) | B5: 0 | C5: 0.05 | D5: 0.25 | E5: 0.35 | F5: 0.25 | G5: 0.05 | H5: 0 | I5: 0 | J5: 0 | K5: 0 | L5: 0.05 | M5: 0 | N5: =SUM(B5:M5)
A6: Prihod | B6: =B5*Prihod!$D$19 | C6: =C5*Prihod!$D$19 | D6: =D5*Prihod!$D$19 | E6: =E5*Prihod!$D$19 | F6: =F5*Prihod!$D$19 | G6: =G5*Prihod!$D$19 | H6: =H5*Prihod!$D$19 | I6: =I5*Prihod!$D$19 | ... M6: =M5*Prihod!$D$19 | N6: =SUM(B6:M6)
A7: Troškovi | B7: =-Pretpostavke!$B$65/12 | C7: =-Pretpostavke!$B$65/12 | D7: =-Pretpostavke!$B$65/12 | E7: =-Pretpostavke!$B$65/12 | F7: =-Pretpostavke!$B$65/12 | G7: =-Pretpostavke!$B$65/12 | H7: =-Pretpostavke!$B$65/12 | I7: =-Pretpostavke!$B$65/12 | ... M7: =-Pretpostavke!$B$65/12 | N7: =SUM(B7:M7)
A8: Neto | B8: =B6+B7 | C8: =C6+C7 | D8: =D6+D7 | E8: =E6+E7 | F8: =F6+F7 | G8: =G6+G7 | H8: =H6+H7 | I8: =I6+I7 | ... N8: =N6+N7
A9: Kumulativno | B9: =B8 | C9: =B9+C8 | D9: =C9+D8 | E9: =D9+E8 | F9: =E9+F8 | G9: =F9+G8 | H9: =G9+H8 | I9: =H9+I8 | J9: =I9+J8 | ... M9: =L9+M8
A11: Raspored uplata je pretpostavka — promeni plavi red ako se tvoja praksa razlikuje. Troškovi su ravnomerno raspoređeni; ako neka stavka nije, razdvoj je u poseban red.

Sheet Scenariji
A1: Poređenje scenarija
A2: Sve vrednosti se izvode iz Pretpostavki i ostalih listova.
A4: Pokazatelj | B4: Scenario A | C4: Scenario B | D4: Scenario C | E4: Napomena
A5: Novih klijenata | B5: =Pretpostavke!$B$40 | C5: =Pretpostavke!$B$41 | D5: =Pretpostavke!$B$42
A6: Ukupno klijenata | B6: =Pretpostavke!$D$40 | C6: =Pretpostavke!$D$41 | D6: =Pretpostavke!$D$42
A7: Ukupan ARR | B7: =Prihod!$D$17 | C7: =Prihod!$D$18 | D7: =Prihod!$D$19
A8: Prihod po klijentu | B8: =IFERROR(B7/B6,0) | C8: =IFERROR(C7/C6,0) | D8: =IFERROR(D7/D6,0)
A9: Troškovi | B9: =Pretpostavke!$B$65 | C9: =Pretpostavke!$B$65 | D9: =Pretpostavke!$B$65 | E9: isti u sva tri dok se ne razdvoje
A10: Neto rezultat | B10: =B7-B9 | C10: =C7-C9 | D10: =D7-D9 | E10: nema smisla dok troškovi nisu popunjeni
A11: Potrebno sati godišnje | B11: =Kapacitet!$B$13 | C11: =Kapacitet!$C$13 | D11: =Kapacitet!$D$13 | E11: kolone 8 / 12 / 18 klijenata
A12: Druga osoba obavezna | B12: =IF(B6>=15,"DA","ne još") | C12: =IF(C6>=15,"DA","ne još") | D12: =IF(D6>=15,"DA","ne još") | E12: prag iz BC3 i 336
