Workbook

Sheet Ponuda
A1: AgriX | E1: PONUDA
A2: Softver za otkup i hladnjače | E2: broj: | F2: P-2026-___
E3: datum: | F3: __.__.2026.
A6: PODACI O KORISNIKU
A7: Poslovno ime
A8: Adresa
A9: PIB / matični broj
A10: Kontakt osoba
A11: Telefon i email
A13: PREDMET PONUDE
B14: Stavka | C14: Količina | D14: Cena | E14: Iznos | F14: Napomena
A15: 1 | B15: AgriX Desktop all-in | C15: 1 | D15: =IFERROR(INDEX(Cenovnik!$B$5:$B$25,MATCH($B$15,Cenovnik!$A$5:$A$25,0)),0) | E15: =C15*D15 | F15: jedno pravno lice, do 5 stanica
A16: 2 | B16: Dodatne otkupne stanice | C16: =MAX(0,$F$16-5) | D16: =INDEX(Cenovnik!$B$5:$B$25,MATCH("Stanica preko pet",Cenovnik!$A$5:$A$25,0)) | E16: =C16*D16 | F16: 10
F17: ↑ upiši ukupan broj aktivnih stanica
A18: 3 | B18: Modul Hladnjača / Proizvodnja | C18: 0 | D18: =INDEX(Cenovnik!$B$5:$B$25,MATCH("Modul Hladnjača / Proizvodnja",Cenovnik!$A$5:$A$25,0)) | E18: =C18*D18 | F18: po proizvodnom pogonu; dodatni pogon 200 € (412, 421)
A19: 4 | B19: Modul SEF | C19: 0 | D19: =INDEX(Cenovnik!$B$5:$B$25,MATCH("Modul SEF",Cenovnik!$A$5:$A$25,0)) | E19: =C19*D19 | F19: 0 = ne uzima, 1 = uzima
A20: 5 | B20: Modul Banka | C20: 0 | D20: =INDEX(Cenovnik!$B$5:$B$25,MATCH("Modul Banka",Cenovnik!$A$5:$A$25,0)) | E20: =C20*D20 | F20: 0 = ne uzima, 1 = uzima
A21: 6 | B21: Modul Dispatch | C21: 0 | D21: =INDEX(Cenovnik!$B$5:$B$25,MATCH("Modul Dispatch",Cenovnik!$A$5:$A$25,0)) | E21: =C21*D21 | F21: zahteva Mobile paket
A22: 7 | B22: Modul GGAP | C22: 0 | D22: =INDEX(Cenovnik!$B$5:$B$25,MATCH("Modul GGAP",Cenovnik!$A$5:$A$25,0)) | E22: =C22*D22 | F22: od 1.000 € — na upit, uz potvrdu obima, nije deo standardne ponude (417)
A23: 8 | B23: Gazdinstvo Pro — nalozi kooperanata | C23: 0 | D23: =INDEX(Cenovnik!$B$5:$B$25,MATCH("Gazdinstvo Pro — kanalska cena",Cenovnik!$A$5:$A$25,0)) | E23: =C23*D23 | F23: kanalska cena, prvih 50 Basic bez naknade
A24: 9 | B24: Hardverska podrška | C24: 0 | D24: =INDEX(Cenovnik!$B$5:$B$25,MATCH("Hardverska podrška — po stanici",Cenovnik!$A$5:$A$25,0)) | E24: =IF(C24=0,0,MAX(INDEX(Cenovnik!$B$5:$B$25,MATCH("Hardverska podrška — minimum",Cenovnik!$A$5:$A$25,0)),$F$16*D24)) | F24: 0 ili 1; obračun po broju stanica, min. 200 €
B26: UKUPNO GODIŠNJE | E26: =SUM(E15:E24)
B27: Kurs za informativni preračun | C27: 117 | E27: =E26*C27 | F27: informativno; plaća se po kursu na dan uplate
A29: JEDNOKRATNE USLUGE
B30: Usluga | C30: Sati | D30: Cena | E30: Iznos | F30: Napomena
B31: Složena migracija podataka | C31: 0 | D31: =INDEX(Cenovnik!$B$5:$B$25,MATCH("Satnica — razvojna",Cenovnik!$A$5:$A$25,0)) | E31: =C31*D31 | F31: razvojna satnica 50 €/h (409)
B32: Dodatna obuka preko 5 sati | C32: 0 | D32: =INDEX(Cenovnik!$B$5:$B$25,MATCH("Satnica — implementaciona",Cenovnik!$A$5:$A$25,0)) | E32: =C32*D32 | F32: implementaciona satnica 30 €/h (409); 5 sati je ukljuceno u onboarding
B33: Razvoj po zahtevu | C33: 0 | D33: =INDEX(Cenovnik!$B$5:$B$25,MATCH("Satnica — razvojna",Cenovnik!$A$5:$A$25,0)) | E33: =C33*D33 | F33: razvojna satnica 50 €/h (409); uz procenu i maksimalni budzet
B34: Ukupno jednokratno | E34: =SUM(E31:E33)
A36: UKLJUČENO U GODIŠNJU NAKNADU
B37: · Instalacija sistema i povezivanje svih komponenti
B38: · Implementaciona obuka u trajanju do 5 sati
B39: · Otklanjanje grešaka, bezbednosne ispravke i nove verzije
B40: · Prilagođavanje izmenama propisa — bez naplate
B41: · Podrška telefonom, mejlom i daljinskom dijagnostikom, radnim danima 08–16
B42: · Vikend podrška za kritične incidente tokom sezone, 1. jun — 30. novembar
A44: USLOVI
B45: · Cene su iskazane u evrima, bez PDV-a, na godišnjem nivou.
B46: · Plaćanje se vrši u dinarima, po srednjem kursu NBS na dan uplate.
B47: · Ugovor se zaključuje na 12 meseci; naknada se plaća pre aktivacije.
...

Sheet Cenovnik
A1: Cenovnik — referentni list
A2: Menja se samo kada se promeni odluka o ceni. Ponuda povlači vrednosti odavde.
A4: Stavka | B4: Cena | C4: Izvor | E4: Paketi | F4: Da/Ne
A5: AgriX Desktop | B5: 500 | C5: odluka 349 | E5: AgriX Desktop | F5: Da
A6: AgriX Desktop all-in | B6: 1200 | C6: odluka 349 (revizija 27.07.) — bazna + 700 | E6: AgriX Desktop all-in | F6: Ne
A7: AgriX Mobile | B7: 1500 | C7: odluka 349 | E7: AgriX Mobile
A8: AgriX Mobile all-in | B8: 2200 | C8: odluka 349 (revizija 27.07.) — bazna + 700 | E8: AgriX Mobile all-in
A9: Stanica preko pet | B9: 50 | C9: odluka 351
A10: Modul SEF | B10: 200 | C10: odluka 350
A11: Modul Banka | B11: 200 | C11: odluka 350
A12: Modul Dispatch | B12: 200 | C12: odluka 350 — samo uz Mobile
A13: Modul Hladnjača / Proizvodnja | B13: 400 | C13: odluka 412/421 — po proizvodnom pogonu
A14: Modul GGAP | B14: 1000 | C14: odluka 352/417 — od; na upit, uz potvrdu obima, nije deo standardne ponude
A15: Gazdinstvo Pro — kanalska cena | B15: 20 | C15: odluka 339
A16: Hardverska podrška — po stanici | B16: 40 | C16: odluka 357
A17: Hardverska podrška — minimum | B17: 200 | C17: odluka 357
A18: Satnica — razvojna | B18: 50 | C18: odluka 409 — razvoj, migracija, adapteri, izvestaji, masovne korekcije
A19: Satnica — implementaciona | B19: 30 | C19: odluka 409 — obuka preko 5h, konfiguracija, ciscenje, IT setup, teren
A20: Modul Hladnjača / Proizvodnja — dodatni pogon | B20: 200 | C20: odluka 413 — -50% na dodatnoj instanci
... A25: Savetnik — Enterprise po gazdinstvu [u pripremi] | B25: 10 | C25: odluka 419 — preko 10 — U PRIPREMI (odluka 423): ne uvrstavati u ponudu

Sheet Uputstvo
A1: Kako se koristi
A4: Popuni samo žuta polja. Sve ostalo se računa.
A6: 1. Broj i datum ponude gore desno.
A7: 2. Podatke o korisniku.
A8: 3. Paket — biraj iz padajuće liste u koloni Stavka.
A9: 4. Ukupan broj aktivnih stanica u koloni Napomena kod stavke 2. Model sam oduzima pet uključenih.
A10: 5. Module — upiši 1 ako klijent uzima, 0 ako ne.
A11: 6. Broj Gazdinstvo Pro naloga koje hladnjača finansira.
A12: 7. Hardverska podrška — 1 ili 0; obračun ide po broju stanica sa minimumom od 200 €.
A13: 8. Jednokratne usluge u satima, ako ih ima.
A14: 9. Kurs za informativni preračun u dinare.
A16: Štampa: list Ponuda je podešen za A4, jedna strana po širini. Sačuvaj kao PDF i pošalji.
... A24: Izvor cena: odluke 339, 341, 349, 350, 351, 352, 353, 354, 357, 409–422.
